2025-10-09 10:29:38,085 | INFO | Fetching all students from database...
2025-10-09 10:29:38,086 | INFO | GET /students | Status: 200 | Duration: 0.003s
2025-10-09 10:30:08,045 | ERROR | Exception in GET /error-demo: Simulated error for testing logs
Traceback (most recent call last):
  File "D:\EY-Training-AI-ML\venv\Lib\site-packages\starlette\middleware\base.py", line 151, in call_next
    message = await recv_stream.receive()
              ^^^^^^^^^^^^^^^^^^^^^^^^^^^
  File "D:\EY-Training-AI-ML\venv\Lib\site-packages\anyio\streams\memory.py", line 126, in receive
    raise EndOfStream from None
anyio.EndOfStream

During handling of the above exception, another exception occurred:

Traceback (most recent call last):
  File "D:\EY-Training-AI-ML\09_October\Daily_Activity\middleware_start.py", line 21, in log_requests
    response = await call_next(request)
               ^^^^^^^^^^^^^^^^^^^^^^^^
  File "D:\EY-Training-AI-ML\venv\Lib\site-packages\starlette\middleware\base.py", line 159, in call_next
    raise app_exc
  File "D:\EY-Training-AI-ML\venv\Lib\site-packages\starlette\middleware\base.py", line 144, in coro
    await self.app(scope, receive_or_disconnect, send_no_error)
  File "D:\EY-Training-AI-ML\venv\Lib\site-packages\starlette\middleware\exceptions.py", line 63, in __call__
    await wrap_app_handling_exceptions(self.app, conn)(scope, receive, send)
  File "D:\EY-Training-AI-ML\venv\Lib\site-packages\starlette\_exception_handler.py", line 53, in wrapped_app
    raise exc
  File "D:\EY-Training-AI-ML\venv\Lib\site-packages\starlette\_exception_handler.py", line 42, in wrapped_app
    await app(scope, receive, sender)
  File "D:\EY-Training-AI-ML\venv\Lib\site-packages\fastapi\middleware\asyncexitstack.py", line 18, in __call__
    await self.app(scope, receive, send)
  File "D:\EY-Training-AI-ML\venv\Lib\site-packages\starlette\routing.py", line 716, in __call__
    await self.middleware_stack(scope, receive, send)
  File "D:\EY-Training-AI-ML\venv\Lib\site-packages\starlette\routing.py", line 736, in app
    await route.handle(scope, receive, send)
  File "D:\EY-Training-AI-ML\venv\Lib\site-packages\starlette\routing.py", line 290, in handle
    await self.app(scope, receive, send)
  File "D:\EY-Training-AI-ML\venv\Lib\site-packages\fastapi\routing.py", line 123, in app
    await wrap_app_handling_exceptions(app, request)(scope, receive, send)
  File "D:\EY-Training-AI-ML\venv\Lib\site-packages\starlette\_exception_handler.py", line 53, in wrapped_app
    raise exc
  File "D:\EY-Training-AI-ML\venv\Lib\site-packages\starlette\_exception_handler.py", line 42, in wrapped_app
    await app(scope, receive, sender)
  File "D:\EY-Training-AI-ML\venv\Lib\site-packages\fastapi\routing.py", line 109, in app
    response = await f(request)
               ^^^^^^^^^^^^^^^^
  File "D:\EY-Training-AI-ML\venv\Lib\site-packages\fastapi\routing.py", line 387, in app
    raw_response = await run_endpoint_function(
                   ^^^^^^^^^^^^^^^^^^^^^^^^^^^^
  File "D:\EY-Training-AI-ML\venv\Lib\site-packages\fastapi\routing.py", line 290, in run_endpoint_function
    return await run_in_threadpool(dependant.call, **values)
           ^^^^^^^^^^^^^^^^^^^^^^^^^^^^^^^^^^^^^^^^^^^^^^^^^
  File "D:\EY-Training-AI-ML\venv\Lib\site-packages\starlette\concurrency.py", line 38, in run_in_threadpool
    return await anyio.to_thread.run_sync(func)
           ^^^^^^^^^^^^^^^^^^^^^^^^^^^^^^^^^^^^
  File "D:\EY-Training-AI-ML\venv\Lib\site-packages\anyio\to_thread.py", line 56, in run_sync
    return await get_async_backend().run_sync_in_worker_thread(
           ^^^^^^^^^^^^^^^^^^^^^^^^^^^^^^^^^^^^^^^^^^^^^^^^^^^^
  File "D:\EY-Training-AI-ML\venv\Lib\site-packages\anyio\_backends\_asyncio.py", line 2485, in run_sync_in_worker_thread
    return await future
           ^^^^^^^^^^^^
  File "D:\EY-Training-AI-ML\venv\Lib\site-packages\anyio\_backends\_asyncio.py", line 976, in run
    result = context.run(func, *args)
             ^^^^^^^^^^^^^^^^^^^^^^^^
  File "D:\EY-Training-AI-ML\09_October\Daily_Activity\middleware_start.py", line 44, in error_demo
    raise ValueError("Simulated error for testing logs")
ValueError: Simulated error for testing logs

2025-10-09 10:30:08,148 | ERROR | Unhandled error in /error-demo: Simulated error for testing logs
  + Exception Group Traceback (most recent call last):
  |   File "D:\EY-Training-AI-ML\venv\Lib\site-packages\starlette\_utils.py", line 79, in collapse_excgroups
  |     yield
  |   File "D:\EY-Training-AI-ML\venv\Lib\site-packages\starlette\middleware\base.py", line 183, in __call__
  |     async with anyio.create_task_group() as task_group:
  |   File "D:\EY-Training-AI-ML\venv\Lib\site-packages\anyio\_backends\_asyncio.py", line 781, in __aexit__
  |     raise BaseExceptionGroup(
  | ExceptionGroup: unhandled errors in a TaskGroup (1 sub-exception)
  +-+---------------- 1 ----------------
    | Traceback (most recent call last):
    |   File "D:\EY-Training-AI-ML\venv\Lib\site-packages\starlette\middleware\errors.py", line 164, in __call__
    |     await self.app(scope, receive, _send)
    |   File "D:\EY-Training-AI-ML\venv\Lib\site-packages\starlette\middleware\base.py", line 182, in __call__
    |     with recv_stream, send_stream, collapse_excgroups():
    |   File "C:\Users\user1\AppData\Local\Programs\Python\Python311\Lib\contextlib.py", line 155, in __exit__
    |     self.gen.throw(typ, value, traceback)
    |   File "D:\EY-Training-AI-ML\venv\Lib\site-packages\starlette\_utils.py", line 85, in collapse_excgroups
    |     raise exc
    |   File "D:\EY-Training-AI-ML\venv\Lib\site-packages\starlette\middleware\base.py", line 184, in __call__
    |     response = await self.dispatch_func(request, call_next)
    |                ^^^^^^^^^^^^^^^^^^^^^^^^^^^^^^^^^^^^^^^^^^^^
    |   File "D:\EY-Training-AI-ML\09_October\Daily_Activity\middleware_start.py", line 27, in log_requests
    |     raise e
    |   File "D:\EY-Training-AI-ML\09_October\Daily_Activity\middleware_start.py", line 21, in log_requests
    |     response = await call_next(request)
    |                ^^^^^^^^^^^^^^^^^^^^^^^^
    |   File "D:\EY-Training-AI-ML\venv\Lib\site-packages\starlette\middleware\base.py", line 159, in call_next
    |     raise app_exc
    |   File "D:\EY-Training-AI-ML\venv\Lib\site-packages\starlette\middleware\base.py", line 144, in coro
    |     await self.app(scope, receive_or_disconnect, send_no_error)
    |   File "D:\EY-Training-AI-ML\venv\Lib\site-packages\starlette\middleware\exceptions.py", line 63, in __call__
    |     await wrap_app_handling_exceptions(self.app, conn)(scope, receive, send)
    |   File "D:\EY-Training-AI-ML\venv\Lib\site-packages\starlette\_exception_handler.py", line 53, in wrapped_app
    |     raise exc
    |   File "D:\EY-Training-AI-ML\venv\Lib\site-packages\starlette\_exception_handler.py", line 42, in wrapped_app
    |     await app(scope, receive, sender)
    |   File "D:\EY-Training-AI-ML\venv\Lib\site-packages\fastapi\middleware\asyncexitstack.py", line 18, in __call__
    |     await self.app(scope, receive, send)
    |   File "D:\EY-Training-AI-ML\venv\Lib\site-packages\starlette\routing.py", line 716, in __call__
    |     await self.middleware_stack(scope, receive, send)
    |   File "D:\EY-Training-AI-ML\venv\Lib\site-packages\starlette\routing.py", line 736, in app
    |     await route.handle(scope, receive, send)
    |   File "D:\EY-Training-AI-ML\venv\Lib\site-packages\starlette\routing.py", line 290, in handle
    |     await self.app(scope, receive, send)
    |   File "D:\EY-Training-AI-ML\venv\Lib\site-packages\fastapi\routing.py", line 123, in app
    |     await wrap_app_handling_exceptions(app, request)(scope, receive, send)
    |   File "D:\EY-Training-AI-ML\venv\Lib\site-packages\starlette\_exception_handler.py", line 53, in wrapped_app
    |     raise exc
    |   File "D:\EY-Training-AI-ML\venv\Lib\site-packages\starlette\_exception_handler.py", line 42, in wrapped_app
    |     await app(scope, receive, sender)
    |   File "D:\EY-Training-AI-ML\venv\Lib\site-packages\fastapi\routing.py", line 109, in app
    |     response = await f(request)
    |                ^^^^^^^^^^^^^^^^
    |   File "D:\EY-Training-AI-ML\venv\Lib\site-packages\fastapi\routing.py", line 387, in app
    |     raw_response = await run_endpoint_function(
    |                    ^^^^^^^^^^^^^^^^^^^^^^^^^^^^
    |   File "D:\EY-Training-AI-ML\venv\Lib\site-packages\fastapi\routing.py", line 290, in run_endpoint_function
    |     return await run_in_threadpool(dependant.call, **values)
    |            ^^^^^^^^^^^^^^^^^^^^^^^^^^^^^^^^^^^^^^^^^^^^^^^^^
    |   File "D:\EY-Training-AI-ML\venv\Lib\site-packages\starlette\concurrency.py", line 38, in run_in_threadpool
    |     return await anyio.to_thread.run_sync(func)
    |            ^^^^^^^^^^^^^^^^^^^^^^^^^^^^^^^^^^^^
    |   File "D:\EY-Training-AI-ML\venv\Lib\site-packages\anyio\to_thread.py", line 56, in run_sync
    |     return await get_async_backend().run_sync_in_worker_thread(
    |            ^^^^^^^^^^^^^^^^^^^^^^^^^^^^^^^^^^^^^^^^^^^^^^^^^^^^
    |   File "D:\EY-Training-AI-ML\venv\Lib\site-packages\anyio\_backends\_asyncio.py", line 2485, in run_sync_in_worker_thread
    |     return await future
    |            ^^^^^^^^^^^^
    |   File "D:\EY-Training-AI-ML\venv\Lib\site-packages\anyio\_backends\_asyncio.py", line 976, in run
    |     result = context.run(func, *args)
    |              ^^^^^^^^^^^^^^^^^^^^^^^^
    |   File "D:\EY-Training-AI-ML\09_October\Daily_Activity\middleware_start.py", line 44, in error_demo
    |     raise ValueError("Simulated error for testing logs")
    | ValueError: Simulated error for testing logs
    +------------------------------------

During handling of the above exception, another exception occurred:

Traceback (most recent call last):
  File "D:\EY-Training-AI-ML\venv\Lib\site-packages\starlette\middleware\errors.py", line 164, in __call__
    await self.app(scope, receive, _send)
  File "D:\EY-Training-AI-ML\venv\Lib\site-packages\starlette\middleware\base.py", line 182, in __call__
    with recv_stream, send_stream, collapse_excgroups():
  File "C:\Users\user1\AppData\Local\Programs\Python\Python311\Lib\contextlib.py", line 155, in __exit__
    self.gen.throw(typ, value, traceback)
  File "D:\EY-Training-AI-ML\venv\Lib\site-packages\starlette\_utils.py", line 85, in collapse_excgroups
    raise exc
  File "D:\EY-Training-AI-ML\venv\Lib\site-packages\starlette\middleware\base.py", line 184, in __call__
    response = await self.dispatch_func(request, call_next)
               ^^^^^^^^^^^^^^^^^^^^^^^^^^^^^^^^^^^^^^^^^^^^
  File "D:\EY-Training-AI-ML\09_October\Daily_Activity\middleware_start.py", line 27, in log_requests
    raise e
  File "D:\EY-Training-AI-ML\09_October\Daily_Activity\middleware_start.py", line 21, in log_requests
    response = await call_next(request)
               ^^^^^^^^^^^^^^^^^^^^^^^^
  File "D:\EY-Training-AI-ML\venv\Lib\site-packages\starlette\middleware\base.py", line 159, in call_next
    raise app_exc
  File "D:\EY-Training-AI-ML\venv\Lib\site-packages\starlette\middleware\base.py", line 144, in coro
    await self.app(scope, receive_or_disconnect, send_no_error)
  File "D:\EY-Training-AI-ML\venv\Lib\site-packages\starlette\middleware\exceptions.py", line 63, in __call__
    await wrap_app_handling_exceptions(self.app, conn)(scope, receive, send)
  File "D:\EY-Training-AI-ML\venv\Lib\site-packages\starlette\_exception_handler.py", line 53, in wrapped_app
    raise exc
  File "D:\EY-Training-AI-ML\venv\Lib\site-packages\starlette\_exception_handler.py", line 42, in wrapped_app
    await app(scope, receive, sender)
  File "D:\EY-Training-AI-ML\venv\Lib\site-packages\fastapi\middleware\asyncexitstack.py", line 18, in __call__
    await self.app(scope, receive, send)
  File "D:\EY-Training-AI-ML\venv\Lib\site-packages\starlette\routing.py", line 716, in __call__
    await self.middleware_stack(scope, receive, send)
  File "D:\EY-Training-AI-ML\venv\Lib\site-packages\starlette\routing.py", line 736, in app
    await route.handle(scope, receive, send)
  File "D:\EY-Training-AI-ML\venv\Lib\site-packages\starlette\routing.py", line 290, in handle
    await self.app(scope, receive, send)
  File "D:\EY-Training-AI-ML\venv\Lib\site-packages\fastapi\routing.py", line 123, in app
    await wrap_app_handling_exceptions(app, request)(scope, receive, send)
  File "D:\EY-Training-AI-ML\venv\Lib\site-packages\starlette\_exception_handler.py", line 53, in wrapped_app
    raise exc
  File "D:\EY-Training-AI-ML\venv\Lib\site-packages\starlette\_exception_handler.py", line 42, in wrapped_app
    await app(scope, receive, sender)
  File "D:\EY-Training-AI-ML\venv\Lib\site-packages\fastapi\routing.py", line 109, in app
    response = await f(request)
               ^^^^^^^^^^^^^^^^
  File "D:\EY-Training-AI-ML\venv\Lib\site-packages\fastapi\routing.py", line 387, in app
    raw_response = await run_endpoint_function(
                   ^^^^^^^^^^^^^^^^^^^^^^^^^^^^
  File "D:\EY-Training-AI-ML\venv\Lib\site-packages\fastapi\routing.py", line 290, in run_endpoint_function
    return await run_in_threadpool(dependant.call, **values)
           ^^^^^^^^^^^^^^^^^^^^^^^^^^^^^^^^^^^^^^^^^^^^^^^^^
  File "D:\EY-Training-AI-ML\venv\Lib\site-packages\starlette\concurrency.py", line 38, in run_in_threadpool
    return await anyio.to_thread.run_sync(func)
           ^^^^^^^^^^^^^^^^^^^^^^^^^^^^^^^^^^^^
  File "D:\EY-Training-AI-ML\venv\Lib\site-packages\anyio\to_thread.py", line 56, in run_sync
    return await get_async_backend().run_sync_in_worker_thread(
           ^^^^^^^^^^^^^^^^^^^^^^^^^^^^^^^^^^^^^^^^^^^^^^^^^^^^
  File "D:\EY-Training-AI-ML\venv\Lib\site-packages\anyio\_backends\_asyncio.py", line 2485, in run_sync_in_worker_thread
    return await future
           ^^^^^^^^^^^^
  File "D:\EY-Training-AI-ML\venv\Lib\site-packages\anyio\_backends\_asyncio.py", line 976, in run
    result = context.run(func, *args)
             ^^^^^^^^^^^^^^^^^^^^^^^^
  File "D:\EY-Training-AI-ML\09_October\Daily_Activity\middleware_start.py", line 44, in error_demo
    raise ValueError("Simulated error for testing logs")
ValueError: Simulated error for testing logs

